<?xml version="1.0" ?>
<!-- =================================================================================== -->
<!-- |    This document was autogenerated by xacro from one_finger_sphere_tip.urdf.xacro | -->
<!-- |    EDITING THIS FILE BY HAND IS NOT RECOMMENDED                                 | -->
<!-- =================================================================================== -->
<robot name="3FingersRobot" xmlns:xacro="http://www.ros.org/wiki.xacro">
  <material name="white">
    <color rgba="0.8 0.8 0.8 1"/>
  </material>
  <material name="blue">
    <color rgba="0 0 0.8 1"/>
  </material>
  <material name="green">
    <color rgba="0 0.8 0 1"/>
  </material>
  <link name="base_link">
    <visual>
      <geometry>
        <box size="0.1 0.1 0.05"/>
      </geometry>
      <material name="white"/>
    </visual>
    <collision>
      <geometry>
        <box size="0.1 0.1 0.05"/>
      </geometry>
    </collision>
    <inertial>
      <mass value="1"/>
      <inertia ixx="1e-3" ixy="0" ixz="0" iyy="1e-3" iyz="0" izz="1e-3"/>
      <origin xyz="0 0 0"/>
    </inertial>
  </link>
  <link name="root_finger">
    <visual>
      <geometry>
        <box size="0.15 0.02 0.005"/>
      </geometry>
      <origin xyz="0.075 0 0"/>
    </visual>
    <collision>
      <geometry>
        <box size="0.15 0.02 0.005"/>
      </geometry>
      <origin xyz="0.075 0 0"/>
    </collision>
    <inertial>
      <origin xyz="0.075 0 0"/>
      <mass value="0.5"/>
      <inertia ixx="1.77083333333e-05" ixy="0" ixz="0" iyy="0.000938541666667" iyz="0" izz="0.000954166666667"/>
    </inertial>
  </link>
  <link name="top_finger">
    <visual>
      <geometry>
        <box size="0.09 0.02 0.005"/>
      </geometry>
      <origin xyz="0.045 0 0"/>
    </visual>
    <visual>
      <geometry>
        <cylinder length="0.005" radius="0.01"/>
      </geometry>
      <origin xyz="0.09"/>
    </visual>
    <collision>
      <geometry>
        <box size="0.09 0.02 0.005"/>
      </geometry>
      <origin xyz="0.045 0 0"/>
    </collision>
    <collision>
      <geometry>
        <cylinder length="0.005" radius="0.02"/>
      </geometry>
    </collision>
    <inertial>
      <origin xyz="0.05 0 0"/>
      <mass value="0.5"/>
      <inertia ixx="1.77083333333e-05" ixy="0" ixz="0" iyy="0.000417708333333" iyz="0" izz="0.000433333333333"/>
    </inertial>
  </link>
  <joint name="base_to_root_joint" type="revolute">
    <parent link="base_link"/>
    <child link="root_finger"/>
    <origin xyz="0 0 0.0525"/>
    <axis xyz="0 0 1"/>
    <limit effort="1000.0" lower="-3.14" upper="3.14" velocity="0.5"/>
    <dynamics damping="0" friction="0"/>
  </joint>
  <joint name="root_to_top_joint" type="revolute">
    <parent link="root_finger"/>
    <child link="top_finger"/>
    <origin xyz="0.15 0 0"/>
    <axis xyz="0 0 1"/>
    <limit effort="1000.0" lower="-3.14" upper="3.14" velocity="0.5"/>
    <dynamics damping="0" friction="0"/>
  </joint>
</robot>

