<?xml version="1.0" ?>
<!-- =================================================================================== -->
<!-- |    This document was autogenerated by xacro from pole.urdf.xacro                | -->
<!-- |    EDITING THIS FILE BY HAND IS NOT RECOMMENDED                                 | -->
<!-- =================================================================================== -->
<robot name="3FingersRobot" xmlns:xacro="http://www.ros.org/wiki.xacro">
  <material name="white">
    <color rgba="0.8 0.8 0.8 1"/>
  </material>
  <material name="blue">
    <color rgba="0 0 0.8 1"/>
  </material>
  <material name="green">
    <color rgba="0 0.8 0 1"/>
  </material>
  <link name="base_link">
    <inertial>
      <mass value="0"/>
      <inertia ixx="1e-3" ixy="0.0" ixz="0.0" iyy="1e-3" iyz="0.0" izz="1e-3"/>
    </inertial>
  </link>
  <!-- dummy link for 2D constraints -->
  <link name="dummy_link_1">
    <inertial>
      <mass value="0"/>
      <inertia ixx="1e-3" ixy="0.0" ixz="0.0" iyy="1e-3" iyz="0.0" izz="1e-3"/>
    </inertial>
  </link>
  <link name="dummy_link_2">
    <inertial>
      <mass value="0"/>
      <inertia ixx="1e-3" ixy="0.0" ixz="0.0" iyy="1e-3" iyz="0.0" izz="1e-3"/>
    </inertial>
  </link>
  <link name="target_pole">
    <visual>
      <geometry>
        <box size="0.5 0.02 0.005"/>
      </geometry>
      <origin xyz="0 0 0"/>
    </visual>
    <collision>
      <geometry>
        <box size="0.5 0.02 0.005"/>
      </geometry>
      <origin xyz="0 0 0"/>
    </collision>
    <inertial>
      <origin xyz="0 0 0"/>
      <mass value="0.5"/>
      <inertia ixx="1.77083333333e-05" ixy="0" ixz="0" iyy="0.0104177083333" iyz="0" izz="0.0104333333333"/>
    </inertial>
  </link>
  <joint name="base_link_prismatic1" type="prismatic">
    <parent link="base_link"/>
    <child link="dummy_link_1"/>
    <origin xyz="0 0 0"/>
    <axis xyz="1 0 0"/>
    <dynamics damping="0" friction="0"/>
    <limit effort="10000.0" lower="-100" upper="100" velocity="5"/>
  </joint>
  <joint name="base_link_prismatic2" type="prismatic">
    <parent link="dummy_link_1"/>
    <child link="dummy_link_2"/>
    <origin xyz="0 0 0"/>
    <axis xyz="0 1 0"/>
    <limit effort="10000.0" lower="-100" upper="100" velocity="5"/>
    <dynamics damping="0" friction="0"/>
  </joint>
  <joint name="base_link_revolute" type="revolute">
    <parent link="dummy_link_2"/>
    <child link="target_pole"/>
    <origin xyz="0 0 0"/>
    <axis xyz="0 0 1"/>
    <limit effort="10000.0" lower="-3.14" upper="3.14" velocity="5"/>
    <dynamics damping="0" friction="0"/>
  </joint>
  <!--<link name="contact_point_1">-->
  <!--<visual>-->
  <!--<geometry>-->
  <!--<sphere radius="${pole_thick*0.5}"/>-->
  <!--</geometry>-->
  <!--<material name="blue" />-->
  <!--</visual>-->
  <!--</link>-->
  <!--<link name="contact_point_2">-->
  <!--<visual>-->
  <!--<geometry>-->
  <!--<sphere radius="${pole_thick*0.5}"/>-->
  <!--</geometry>-->
  <!--<material name="blue" />-->
  <!--</visual>-->
  <!--</link>-->
  <!--<link name="contact_point_3">-->
  <!--<visual>-->
  <!--<geometry>-->
  <!--<sphere radius="${pole_thick*0.5}"/>-->
  <!--</geometry>-->
  <!--<material name="blue" />-->
  <!--</visual>-->
  <!--</link>-->
  <!--<joint name="contact_point_1_joint" type='fixed'>-->
  <!--<parent link="target_pole"/>-->
  <!--<child link="contact_point_1"/>-->
  <!--<origin xyz="0 0 0.02" />-->
  <!--</joint>-->
  <!--<joint name="contact_point_2_joint" type='fixed'>-->
  <!--<parent link="target_pole"/>-->
  <!--<child link="contact_point_2"/>-->
  <!--<origin xyz="${-dist_contact_pts} 0 0.02" />-->
  <!--</joint>	-->
  <!--<joint name="contact_point_3_joint" type='fixed'>-->
  <!--<parent link="target_pole"/>-->
  <!--<child link="contact_point_3"/>-->
  <!--<origin xyz="${dist_contact_pts} 0 0.02" />-->
  <!--</joint>-->
</robot>

