<?xml version="1.0" ?>
<!-- =================================================================================== -->
<!-- |    This document was autogenerated by xacro from three_fingers_rect.urdf.xacro  | -->
<!-- |    EDITING THIS FILE BY HAND IS NOT RECOMMENDED                                 | -->
<!-- =================================================================================== -->
<robot name="3FingersRobot" xmlns:xacro="http://www.ros.org/wiki.xacro">
  <material name="white">
    <color rgba="0.8 0.8 0.8 1"/>
  </material>
  <material name="blue">
    <color rgba="0 0 0.8 1"/>
  </material>
  <material name="green">
    <color rgba="0 0.8 0 1"/>
  </material>
  <link name="base_link">
    <visual>
      <geometry>
        <box size="0.6 0.4 0.02"/>
      </geometry>
      <origin xyz="0 0 0"/>
      <material name="white"/>
    </visual>
    <collision>
      <geometry>
        <box size="0.6 0.4 0.02"/>
      </geometry>
      <origin xyz="0 0 0"/>
    </collision>
    <inertial>
      <mass value="0"/>
      <inertia ixx="1e-3" ixy="0.0" ixz="0.0" iyy="1e-3" iyz="0.0" izz="1e-3"/>
    </inertial>
  </link>
  <link name="1_root_finger">
    <visual>
      <geometry>
        <cylinder length="0.02" radius="0.011"/>
      </geometry>
      <origin xyz="0 0 0"/>
    </visual>
    <visual>
      <geometry>
        <box size="0.15 0.02 0.005"/>
      </geometry>
      <origin xyz="0.075 0 0"/>
    </visual>
    <collision>
      <geometry>
        <box size="0.15 0.02 0.005"/>
      </geometry>
      <origin xyz="0.075 0 0"/>
    </collision>
    <inertial>
      <origin xyz="0.075 0 0"/>
      <mass value="0.5"/>
      <inertia ixx="1.77083333333e-05" ixy="0" ixz="0" iyy="0.000938541666667" iyz="0" izz="0.000954166666667"/>
    </inertial>
  </link>
  <joint name="1_base_to_root" type="revolute">
    <parent link="base_link"/>
    <child link="1_root_finger"/>
    <origin rpy="0 0 3.1415/2.0" xyz="0 0.2 0.02"/>
    <axis xyz="0 0 1"/>
    <limit effort="10000.0" lower="-3.14" upper="3.14" velocity="5"/>
    <dynamics damping="0" friction="0"/>
  </joint>
  <link name="1_top_finger">
    <visual>
      <geometry>
        <box size="0.1 0.02 0.005"/>
      </geometry>
      <origin xyz="0.05 0 0"/>
      <material name="green"/>
    </visual>
    <collision>
      <geometry>
        <box size="0.1 0.02 0.005"/>
      </geometry>
      <origin xyz="0.05 0 0"/>
    </collision>
    <inertial>
      <origin xyz="0.05 0 0"/>
      <mass value="0.5"/>
      <inertia ixx="3.33333333333e-05" ixy="0" ixz="0" iyy="0.000433333333333" iyz="0" izz="0.000433333333333"/>
    </inertial>
  </link>
  <joint name="1_root_to_top" type="revolute">
    <parent link="1_root_finger"/>
    <child link="1_top_finger"/>
    <origin xyz="0.15 0 0"/>
    <axis xyz="0 0 1"/>
    <limit effort="10000.0" lower="-3.14" upper="3.14" velocity="5"/>
    <dynamics damping="0" friction="0"/>
  </joint>
  <link name="2_root_finger">
    <visual>
      <geometry>
        <cylinder length="0.02" radius="0.011"/>
      </geometry>
      <origin xyz="0 0 0"/>
    </visual>
    <visual>
      <geometry>
        <box size="0.15 0.02 0.005"/>
      </geometry>
      <origin xyz="0.075 0 0"/>
    </visual>
    <collision>
      <geometry>
        <box size="0.15 0.02 0.005"/>
      </geometry>
      <origin xyz="0.075 0 0"/>
    </collision>
    <inertial>
      <origin xyz="0.075 0 0"/>
      <mass value="0.5"/>
      <inertia ixx="1.77083333333e-05" ixy="0" ixz="0" iyy="0.000938541666667" iyz="0" izz="0.000954166666667"/>
    </inertial>
  </link>
  <joint name="2_base_to_root" type="revolute">
    <parent link="base_link"/>
    <child link="2_root_finger"/>
    <origin rpy="0 0 0" xyz="-0.1 -0.2 0.02"/>
    <axis xyz="0 0 1"/>
    <limit effort="10000.0" lower="-3.14" upper="3.14" velocity="5"/>
    <dynamics damping="0" friction="0"/>
  </joint>
  <link name="2_top_finger">
    <visual>
      <geometry>
        <box size="0.1 0.02 0.005"/>
      </geometry>
      <origin xyz="0.05 0 0"/>
      <material name="green"/>
    </visual>
    <collision>
      <geometry>
        <box size="0.1 0.02 0.005"/>
      </geometry>
      <origin xyz="0.05 0 0"/>
    </collision>
    <inertial>
      <origin xyz="0.05 0 0"/>
      <mass value="0.5"/>
      <inertia ixx="3.33333333333e-05" ixy="0" ixz="0" iyy="0.000433333333333" iyz="0" izz="0.000433333333333"/>
    </inertial>
  </link>
  <joint name="2_root_to_top" type="revolute">
    <parent link="2_root_finger"/>
    <child link="2_top_finger"/>
    <origin xyz="0.15 0 0"/>
    <axis xyz="0 0 1"/>
    <limit effort="10000.0" lower="-3.14" upper="3.14" velocity="5"/>
    <dynamics damping="0" friction="0"/>
  </joint>
  <link name="3_root_finger">
    <visual>
      <geometry>
        <cylinder length="0.02" radius="0.011"/>
      </geometry>
      <origin xyz="0 0 0"/>
    </visual>
    <visual>
      <geometry>
        <box size="0.15 0.02 0.005"/>
      </geometry>
      <origin xyz="0.075 0 0"/>
    </visual>
    <collision>
      <geometry>
        <box size="0.15 0.02 0.005"/>
      </geometry>
      <origin xyz="0.075 0 0"/>
    </collision>
    <inertial>
      <origin xyz="0.075 0 0"/>
      <mass value="0.5"/>
      <inertia ixx="1.77083333333e-05" ixy="0" ixz="0" iyy="0.000938541666667" iyz="0" izz="0.000954166666667"/>
    </inertial>
  </link>
  <joint name="3_base_to_root" type="revolute">
    <parent link="base_link"/>
    <child link="3_root_finger"/>
    <origin rpy="0 0 0" xyz="0.1 -0.2 0.02"/>
    <axis xyz="0 0 1"/>
    <limit effort="10000.0" lower="-3.14" upper="3.14" velocity="5"/>
    <dynamics damping="0" friction="0"/>
  </joint>
  <link name="3_top_finger">
    <visual>
      <geometry>
        <box size="0.1 0.02 0.005"/>
      </geometry>
      <origin xyz="0.05 0 0"/>
      <material name="green"/>
    </visual>
    <collision>
      <geometry>
        <box size="0.1 0.02 0.005"/>
      </geometry>
      <origin xyz="0.05 0 0"/>
    </collision>
    <inertial>
      <origin xyz="0.05 0 0"/>
      <mass value="0.5"/>
      <inertia ixx="3.33333333333e-05" ixy="0" ixz="0" iyy="0.000433333333333" iyz="0" izz="0.000433333333333"/>
    </inertial>
  </link>
  <joint name="3_root_to_top" type="revolute">
    <parent link="3_root_finger"/>
    <child link="3_top_finger"/>
    <origin xyz="0.15 0 0"/>
    <axis xyz="0 0 1"/>
    <limit effort="10000.0" lower="-3.14" upper="3.14" velocity="5"/>
    <dynamics damping="0" friction="0"/>
  </joint>
</robot>

